# Fixing the test_api.py

The `httpx.ConnectError: All connection attempts failed` error in your test indicates that the test client is unable to establish a connection to your FastAPI application running inside a Docker container. This type of error typically arises due to networking issues or misconfigurations in how services are addressed or exposed. Given the context of Docker and `docker-compose`, here are steps to troubleshoot and potentially resolve the issue:

### Verify Networking Configuration

1. **Service Name and Ports**: Confirm that the service name (`python-app`) and port (`8000`) you are using in the test match the configuration in your `docker-compose.yaml`. The service name used in the URL (`http://python-app:8000/process-urls/`) must exactly match the service name defined in `docker-compose.yaml`.

2. **Docker Networking**: By default, Docker Compose creates a default network for the services defined in `docker-compose.yaml`, enabling them to communicate using service names as hostnames. Ensure there are no overrides or configurations that might be affecting this default behavior.

### Ensure Service Readiness

- **Application Readiness**: Make sure the FastAPI application (`python-app`) is fully started and ready to accept connections before the test attempts to make a request. If necessary, implement a wait-for-it script or utilize Docker health checks to ensure `python-app` is ready.

### Examine Docker Compose Logs

- After running `docker-compose up`, carefully review the logs for the `python-app` service to ensure it has started correctly and is listening on the expected port. Look for any errors or warnings that might indicate problems.

### Test Configuration

- **Async Testing**: Given that your test is asynchronous, ensure that the testing environment (including any CI environment where the tests are executed) properly supports asynchronous operations and that `pytest-asyncio` or a similar plugin is correctly configured.

### Testing Outside Docker

- **Local Testing**: If feasible, try to run the FastAPI application locally outside Docker and then run the test pointing to the local instance of the application. This can help determine if the issue is related to Docker networking.

### Adjust Test Command

- Consider simplifying the test execution command in GitHub Actions to directly use `pytest` without `docker-compose exec`, if the testing environment allows for it. This approach might require adjusting how services are accessed based on the environment.

### Consider GitHub Actions Environment

- If you are running this in a GitHub Actions workflow, remember that the workflow executes in a virtual environment where `docker-compose` services might not be directly accessible in the same way as in a local development environment. Adjustments to service accessibility and networking might be necessary.

### Direct Connection Attempt

- As a diagnostic step, try using a tool like `curl` from within the GitHub Actions environment or another container within the same Docker Compose network to manually access the `python-app` endpoint. This can help verify network accessibility.

Moving forward, if adjustments to the networking configuration and service readiness checks don't resolve the issue, further investigation into the specific environment where the tests are run and how Docker Compose services are orchestrated might be necessary.